Workbook

Sheet ⚙️ Master Threshold
A1: ⚙️ MASTER THRESHOLD — Atur Semua Batas Minimum Stok di Sini
A2: ✏️ Ubah angka di kolom THRESHOLD BARU, lalu simpan file. Semua sheet SO akan otomatis mengikuti.
A4: No | B4: NAMA BARANG | C4: AREA / LOKASI | D4: THRESHOLD SAAT INI | E4: THRESHOLD BARU ✏️ | F4: KETERANGAN / CATATAN
A5: ▶ MEJA BIRU DEPAN + CHILLER
A6: 1 | B6: Tepung Terigu | C6: Meja Biru + Chiller | D6: ='Meja Biru + Chiller'!I7 -> 2 | E6: 2
A7: 2 | B7: Bumbu Mix | C7: Meja Biru + Chiller | D7: ='Meja Biru + Chiller'!I8 -> 1 | E7: 1
A8: 3 | B8: Minyak Beku | C8: Meja Biru + Chiller | D8: ='Meja Biru + Chiller'!I9 -> 5 | E8: 5
A9: 4 | B9: Bumbu Marinasi | C9: Meja Biru + Chiller | D9: ='Meja Biru + Chiller'!I10 -> 125 | E9: 125
A10: 5 | B10: Beras | C10: Meja Biru + Chiller | D10: ='Meja Biru + Chiller'!I11 -> 1 | E10: 1
A11: 6 | B11: Mango Mint | C11: Meja Biru + Chiller | D11: ='Meja Biru + Chiller'!I12 -> 8 | E11: 8
A12: 7 | B12: Mint Ice Cream | C12: Meja Biru + Chiller | D12: ='Meja Biru + Chiller'!I13 -> 8 | E12: 8
A13: 8 | B13: Vanilla Rose | C13: Meja Biru + Chiller | D13: ='Meja Biru + Chiller'!I14 -> 8 | E13: 8
A14: 9 | B14: Snowy Cheese | C14: Meja Biru + Chiller | D14: ='Meja Biru + Chiller'!I15 -> 380 | E14: =380 -> 380
A15: 10 | B15: Tepung Panir | C15: Meja Biru + Chiller | D15: ='Meja Biru + Chiller'!I16 -> 125 | E15: 125
A16: 11 | B16: Tepung Corndog | C16: Meja Biru + Chiller | D16: ='Meja Biru + Chiller'!I17 -> 0 | E16: 0
A17: 12 | B17: Cabe Sachet | C17: Meja Biru + Chiller | D17: ='Meja Biru + Chiller'!I18 -> 10 | E17: 10
A18: 13 | B18: Tomat Sachet | C18: Meja Biru + Chiller | D18: ='Meja Biru + Chiller'!I19 -> 10 | E18: 10
A19: 14 | B19: Nori | C19: Meja Biru + Chiller | D19: ='Meja Biru + Chiller'!I20 -> 30 | E19: =30 -> 30
A20: 15 | B20: Biji Wijen | C20: Meja Biru + Chiller | D20: ='Meja Biru + Chiller'!I21 -> 30 | E20: =30 -> 30
A21: 16 | B21: Gula Putih | C21: Meja Biru + Chiller | D21: ='Meja Biru + Chiller'!I22 -> 100 | E21: =100 -> 100
A22: 17 | B22: Garam | C22: Meja Biru + Chiller | D22: ='Meja Biru + Chiller'!I23 -> 20 | E22: =20 -> 20
A23: 18 | B23: Cajun | C23: Meja Biru + Chiller | D23: ='Meja Biru + Chiller'!I24 -> 20 | E23: =20 -> 20
A24: 19 | B24: Samyang | C24: Meja Biru + Chiller | D24: ='Meja Biru + Chiller'!I25 -> 45 | E24: =45 -> 45
A25: 20 | B25: Bon Cabe | C25: Meja Biru + Chiller | D25: ='Meja Biru + Chiller'!I26 -> 1 | E25: 1
A26: 21 | B26: Plastik 15 | C26: Meja Biru + Chiller | D26: ='Meja Biru + Chiller'!I27 -> 1 | E26: 1
A27: 22 | B27: Plastik 24 | C27: Meja Biru + Chiller | D27: ='Meja Biru + Chiller'!I28 -> 1 | E27: 1
A28: 23 | B28: Plastik 30 | C28: Meja Biru + Chiller | D28: ='Meja Biru + Chiller'!I29 -> 1 | E28: 1
A29: 24 | B29: Kaldu Odeng | C29: Meja Biru + Chiller | D29: ='Meja Biru + Chiller'!I30 -> 100 | E29: =100 -> 100
A30: 25 | B30: Baking Soda | C30: Meja Biru + Chiller | D30: ='Meja Biru + Chiller'!I31 -> 0 | E30: 0
A31: 26 | B31: Teh Tong Ji | C31: Meja Biru + Chiller | D31: ='Meja Biru + Chiller'!I32 -> 3 | E31: 3
A32: 27 | B32: Dus Hampers | C32: Meja Biru + Chiller | D32: ='Meja Biru + Chiller'!I33 -> 0 | E32: 0
A33: 28 | B33: Box Berbagi | C33: Meja Biru + Chiller | D33: ='Meja Biru + Chiller'!I34 -> 0 | E33: 0
A34: 29 | B34: Botol Hampers | C34: Meja Biru + Chiller | D34: ='Meja Biru + Chiller'!I35 -> 0 | E34: 0
A35: 30 | B35: Gas Torch | C35: Meja Biru + Chiller | D35: ='Meja Biru + Chiller'!I36 -> 100 | E35: =100 -> 100
A36: 31 | B36: Katsubuoshi | C36: Meja Biru + Chiller | D36: ='Meja Biru + Chiller'!I37 -> 5 | E36: 5
A37: 32 | B37: Spray Lemon Pepper | C37: Meja Biru + Chiller | D37: ='Meja Biru + Chiller'!I38 -> 40 | E37: 40
A38: 33 | B38: Minyak Truffel | C38: Meja Biru + Chiller | D38: ='Meja Biru + Chiller'!I39 -> 100 | E38: 100
A39: =A38+1 -> 34 | B39: Ultra (susu) | C39: Meja Biru + Chiller | D39: ='Meja Biru + Chiller'!I41 -> 250 | E39: 250
A40: =A39+1 -> 35 | B40: Air Gula | C40: Meja Biru + Chiller | D40: ='Meja Biru + Chiller'!I42 -> 100 | E40: 100
A41: =A40+1 -> 36 | B41: Mozzarella | C41: Meja Biru + Chiller | D41: ='Meja Biru + Chiller'!I43 -> 200 | E41: 200
...

Sheet Meja Biru + Chiller
A1: 📋 STOK OPNAME HARIAN — MEJA BIRU DEPAN + CHILLER
A2: TANGGAL / HARI | C2: 46257 | E2: HARI | G2: =TEXT(C2,"DDDD") -> Sunday | I2: NAMA PETUGAS | K2: Candra
A3: KETERANGAN WARNA STATUS: 🔴 STOK HABIS / KRITIS 🟠 STOK HAMPIR HABIS (< 2× Threshold) 🟢 STOK AMAN
A5: No | B5: NAMA BARANG | C5: STEP 1 HITUNG UTUH (Qty) | D5: STEP 2 HITUNG TERBUKA (Qty) | E5: SATUAN | F5: TOTAL (Step1 + Step2) | G5: KONVERSI (Isi per Pack) | H5: KONVERSI (Keterangan) | I5: MIN THRESHOLD | J5: STATUS STOK | L5: REQUEST BARANG HABIS / KRITIS | M5: QTY Request
A6: ▶ MEJA BIRU DEPAN
A7: 1 | B7: Tepung Terigu | C7: 4 | D7: 0 | E7: kg | F7: =C7+D7 -> 4 | G7: 1 | H7: 1 Plastik = 1 kg | I7: ='⚙️ Master Threshold'!E6 -> 2 | J7: =IF(I7=0,"—",IF(F7<=I7,"🔴 KRITIS",IF(F7<=I7*2,"🟠 HAMPIR HABIS","🟢 AMAN"))) -> 🟠 HAMPIR HABIS | L7: =IF(J7="🔴 KRITIS",B7,"") | M7: =IF(J7="🔴 KRITIS","SEGERA RESTOCK!",IF(J7="🟠 HAMPIR HABIS","Cek & Restock","")) -> Cek & Restock
A8: 2 | B8: Bumbu Mix | C8: 2 | D8: 0 | E8: pcs | F8: =C8+D8 -> 2 | G8: 450 | H8: 1 Plastik = 450 gr | I8: ='⚙️ Master Threshold'!E7 -> 1 | J8: =IF(I8=0,"—",IF(F8<=I8,"🔴 KRITIS",IF(F8<=I8*2,"🟠 HAMPIR HABIS","🟢 AMAN"))) -> 🟠 HAMPIR HABIS | L8: =IF(J8="🔴 KRITIS",B8,"") | M8: =IF(J8="🔴 KRITIS","SEGERA RESTOCK!",IF(J8="🟠 HAMPIR HABIS","Cek & Restock","")) -> Cek & Restock
A9: 3 | B9: Minyak liquid | C9: 18 | D9: 8 | E9: kg -+ | F9: =C9+D9 -> 26 | G9: 15 | H9: 1 Karton = 15 kg | I9: ='⚙️ Master Threshold'!E8 -> 5 | J9: =IF(I9=0,"—",IF(F9<=I9,"🔴 KRITIS",IF(F9<=I9*2,"🟠 HAMPIR HABIS","🟢 AMAN"))) -> 🟢 AMAN | L9: =IF(J9="🔴 KRITIS",B9,"") | M9: =IF(J9="🔴 KRITIS","SEGERA RESTOCK!",IF(J9="🟠 HAMPIR HABIS","Cek & Restock",""))
A10: 4 | B10: Bumbu Marinasi | C10: 0 | D10: 863 | E10: gr | F10: =C10+D10 -> 863 | G10: 1200 | H10: 1 Pack = 1200 gr | I10: ='⚙️ Master Threshold'!E9 -> 125 | J10: =IF(I10=0,"—",IF(F10<=I10,"🔴 KRITIS",IF(F10<=I10*2,"🟠 HAMPIR HABIS","🟢 AMAN"))) -> 🟢 AMAN | L10: =IF(J10="🔴 KRITIS",B10,"") | M10: =IF(J10="🔴 KRITIS","SEGERA RESTOCK!",IF(J10="🟠 HAMPIR HABIS","Cek & Restock",""))
A11: 5 | B11: Beras | C11: 0 | D11: 2.2 | E11: kg | F11: =C11+D11 -> 2 | G11: 5 | H11: 1 Karung = 5 kg | I11: ='⚙️ Master Threshold'!E10 -> 1 | J11: =IF(I11=0,"—",IF(F11<=I11,"🔴 KRITIS",IF(F11<=I11*2,"🟠 HAMPIR HABIS","🟢 AMAN"))) -> 🟢 AMAN | L11: =IF(J11="🔴 KRITIS",B11,"") | M11: =IF(J11="🔴 KRITIS","SEGERA RESTOCK!",IF(J11="🟠 HAMPIR HABIS","Cek & Restock",""))
A12: 6 | B12: Mango Mint | C12: 0 | D12: 41 | E12: gr | F12: =C12+D12-7 -> 34 | G12: 40 | H12: 1 Pack = 40 gr | I12: ='⚙️ Master Threshold'!E11 -> 8 | J12: =IF(I12=0,"—",IF(F12<=I12,"🔴 KRITIS",IF(F12<=I12*2,"🟠 HAMPIR HABIS","🟢 AMAN"))) -> 🟢 AMAN | L12: =IF(J12="🔴 KRITIS",B12,"") | M12: =IF(J12="🔴 KRITIS","SEGERA RESTOCK!",IF(J12="🟠 HAMPIR HABIS","Cek & Restock",""))
A13: 7 | B13: Mint Ice Cream | C13: 0 | D13: 30 | E13: gr | F13: =C13+D13-7 -> 23 | G13: 40 | H13: 1 Pack = 40 gr | I13: ='⚙️ Master Threshold'!E12 -> 8 | J13: =IF(I13=0,"—",IF(F13<=I13,"🔴 KRITIS",IF(F13<=I13*2,"🟠 HAMPIR HABIS","🟢 AMAN"))) -> 🟢 AMAN | L13: =IF(J13="🔴 KRITIS",B13,"") | M13: =IF(J13="🔴 KRITIS","SEGERA RESTOCK!",IF(J13="🟠 HAMPIR HABIS","Cek & Restock",""))
A14: 8 | B14: Vanilla Rose | C14: 0 | D14: 30 | E14: gr | F14: =C14+D14-7 -> 23 | G14: 40 | H14: 1 Pack = 40 gr | I14: ='⚙️ Master Threshold'!E13 -> 8 | J14: =IF(I14=0,"—",IF(F14<=I14,"🔴 KRITIS",IF(F14<=I14*2,"🟠 HAMPIR HABIS","🟢 AMAN"))) -> 🟢 AMAN | L14: =IF(J14="🔴 KRITIS",B14,"") | M14: =IF(J14="🔴 KRITIS","SEGERA RESTOCK!",IF(J14="🟠 HAMPIR HABIS","Cek & Restock",""))
A15: 9 | B15: Snowy Cheese | C15: 0 | D15: 472 | E15: gr | F15: =C15+D15-115 -> 357 | G15: 380 | H15: 1 Pack = 380 gr | I15: ='⚙️ Master Threshold'!E14 -> 380 | J15: =IF(I15=0,"—",IF(F15<=I15,"🔴 KRITIS",IF(F15<=I15*2,"🟠 HAMPIR HABIS","🟢 AMAN"))) -> 🔴 KRITIS | L15: =IF(J15="🔴 KRITIS",B15,"") -> Snowy Cheese | M15: =IF(J15="🔴 KRITIS","SEGERA RESTOCK!",IF(J15="🟠 HAMPIR HABIS","Cek & Restock","")) -> SEGERA RESTOCK!
A16: 10 | B16: Tepung Panir | C16: 0 | D16: 329 | E16: gr | F16: =C16+D16 -> 329 | G16: 200 | H16: 1 Plastik = 200 gr | I16: ='⚙️ Master Threshold'!E15 -> 125 | J16: =IF(I16=0,"—",IF(F16<=I16,"🔴 KRITIS",IF(F16<=I16*2,"🟠 HAMPIR HABIS","🟢 AMAN"))) -> 🟢 AMAN | L16: =IF(J16="🔴 KRITIS",B16,"") | M16: =IF(J16="🔴 KRITIS","SEGERA RESTOCK!",IF(J16="🟠 HAMPIR HABIS","Cek & Restock",""))
A17: 11 | B17: Tepung Corndog | C17: 0 | D17: 599 | E17: gr | F17: =C17+D17 -> 599 | G17: 1000 | H17: 1 Plastik = 1 kg | I17: ='⚙️ Master Threshold'!E16 -> 0 | J17: =IF(I17=0,"—",IF(F17<=I17,"🔴 KRITIS",IF(F17<=I17*2,"🟠 HAMPIR HABIS","🟢 AMAN"))) -> — | L17: =IF(J17="🔴 KRITIS",B17,"") | M17: =IF(J17="🔴 KRITIS","SEGERA RESTOCK!",IF(J17="🟠 HAMPIR HABIS","Cek & Restock",""))
A18: 12 | B18: Cabe Sachet | C18: 24 | D18: 19 | E18: pcs | F18: =C18+D18 -> 43 | G18: 24 | H18: 1 Pack = 24 pcs | I18: ='⚙️ Master Threshold'!E17 -> 10 | J18: =IF(I18=0,"—",IF(F18<=I18,"🔴 KRITIS",IF(F18<=I18*2,"🟠 HAMPIR HABIS","🟢 AMAN"))) -> 🟢 AMAN | L18: =IF(J18="🔴 KRITIS",B18,"") | M18: =IF(J18="🔴 KRITIS","SEGERA RESTOCK!",IF(J18="🟠 HAMPIR HABIS","Cek & Restock",""))
A19: 13 | B19: Tomat Sachet | C19: 48 | D19: 1 | E19: pcs | F19: =C19+D19 -> 49 | G19: 24 | H19: 1 Pack = 24 pcs | I19: ='⚙️ Master Threshold'!E18 -> 10 | J19: =IF(I19=0,"—",IF(F19<=I19,"🔴 KRITIS",IF(F19<=I19*2,"🟠 HAMPIR HABIS","🟢 AMAN"))) -> 🟢 AMAN | L19: =IF(J19="🔴 KRITIS",B19,"") | M19: =IF(J19="🔴 KRITIS","SEGERA RESTOCK!",IF(J19="🟠 HAMPIR HABIS","Cek & Restock",""))
A20: 14 | B20: Nori | C20: 86 | D20: 23 | E20: gr | F20: =C20+D20-22 -> 87 | G20: 50 | H20: 1 Pack = 50 gr | I20: ='⚙️ Master Threshold'!E19 -> 30 | J20: =IF(I20=0,"—",IF(F20<=I20,"🔴 KRITIS",IF(F20<=I20*2,"🟠 HAMPIR HABIS","🟢 AMAN"))) -> 🟢 AMAN | L20: =IF(J20="🔴 KRITIS",B20,"") | M20: =IF(J20="🔴 KRITIS","SEGERA RESTOCK!",IF(J20="🟠 HAMPIR HABIS","Cek & Restock",""))
A21: 15 | B21: Biji Wijen | C21: =200+44 -> 244 | D21: 51 | E21: gr | F21: =C21+D21-22 -> 273 | G21: 100 | H21: 1 Pack = 100/250 gr | I21: ='⚙️ Master Threshold'!E20 -> 30 | J21: =IF(I21=0,"—",IF(F21<=I21,"🔴 KRITIS",IF(F21<=I21*2,"🟠 HAMPIR HABIS","🟢 AMAN"))) -> 🟢 AMAN | L21: =IF(J21="🔴 KRITIS",B21,"") | M21: =IF(J21="🔴 KRITIS","SEGERA RESTOCK!",IF(J21="🟠 HAMPIR HABIS","Cek & Restock",""))
A22: 16 | B22: Gula Putih | C22: 0 | D22: 295 | E22: gr | F22: =C22+D22-195 -> 100 | G22: 1000 | H22: 1 Plastik = 1 kg | I22: ='⚙️ Master Threshold'!E21 -> 100 | J22: =IF(I22=0,"—",IF(F22<=I22,"🔴 KRITIS",IF(F22<=I22*2,"🟠 HAMPIR HABIS","🟢 AMAN"))) -> 🔴 KRITIS | L22: =IF(J22="🔴 KRITIS",B22,"") -> Gula Putih | M22: =IF(J22="🔴 KRITIS","SEGERA RESTOCK!",IF(J22="🟠 HAMPIR HABIS","Cek & Restock","")) -> SEGERA RESTOCK!
A23: 17 | B23: Garam | C23: 104 | D23: 616 | E23: gr | F23: =C23+D23-265 -> 455 | G23: 400 | H23: 1 Pack = 400 gr | I23: ='⚙️ Master Threshold'!E22 -> 20 | J23: =IF(I23=0,"—",IF(F23<=I23,"🔴 KRITIS",IF(F23<=I23*2,"🟠 HAMPIR HABIS","🟢 AMAN"))) -> 🟢 AMAN | L23: =IF(J23="🔴 KRITIS",B23,"") | M23: =IF(J23="🔴 KRITIS","SEGERA RESTOCK!",IF(J23="🟠 HAMPIR HABIS","Cek & Restock",""))
A24: 18 | B24: Cajun | C24: 0 | D24: 51 | E24: gr | F24: =C24+D24-40 -> 11 | G24: 500 | H24: 1 Pack = 500 gr | I24: ='⚙️ Master Threshold'!E23 -> 20 | J24: =IF(I24=0,"—",IF(F24<=I24,"🔴 KRITIS",IF(F24<=I24*2,"🟠 HAMPIR HABIS","🟢 AMAN"))) -> 🔴 KRITIS | L24: =IF(J24="🔴 KRITIS",B24,"") -> Cajun | M24: =IF(J24="🔴 KRITIS","SEGERA RESTOCK!",IF(J24="🟠 HAMPIR HABIS","Cek & Restock","")) -> SEGERA RESTOCK!
A25: 19 | B25: Samyang | C25: 232 | D25: 79 | E25: gr | F25: =C25+D25-45 -> 266 | G25: 200 | H25: 1 Botol = 200 gr | I25: ='⚙️ Master Threshold'!E24 -> 45 | J25: =IF(I25=0,"—",IF(F25<=I25,"🔴 KRITIS",IF(F25<=I25*2,"🟠 HAMPIR HABIS","🟢 AMAN"))) -> 🟢 AMAN | L25: =IF(J25="🔴 KRITIS",B25,"") | M25: =IF(J25="🔴 KRITIS","SEGERA RESTOCK!",IF(J25="🟠 HAMPIR HABIS","Cek & Restock",""))
A26: 20 | B26: Bon Cabe | C26: 0 | D26: 1 | E26: pcs | F26: =C26+D26 -> 1 | G26: 12 | H26: 1 Pack = 12 sachet | I26: ='⚙️ Master Threshold'!E25 -> 1 | J26: =IF(I26=0,"—",IF(F26<=I26,"🔴 KRITIS",IF(F26<=I26*2,"🟠 HAMPIR HABIS","🟢 AMAN"))) -> 🔴 KRITIS | L26: =IF(J26="🔴 KRITIS",B26,"") -> Bon Cabe | M26: =IF(J26="🔴 KRITIS","SEGERA RESTOCK!",IF(J26="🟠 HAMPIR HABIS","Cek & Restock","")) -> SEGERA RESTOCK!
A27: 21 | B27: Plastik 15 | C27: 0 | D27: 1 | E27: pax | F27: =C27+D27 -> 1 | G27: 1 | H27: 1 Pack | I27: ='⚙️ Master Threshold'!E26 -> 1 | J27: =IF(I27=0,"—",IF(F27<=I27,"🔴 KRITIS",IF(F27<=I27*2,"🟠 HAMPIR HABIS","🟢 AMAN"))) -> 🔴 KRITIS | L27: =IF(J27="🔴 KRITIS",B27,"") -> Plastik 15 | M27: =IF(J27="🔴 KRITIS","SEGERA RESTOCK!",IF(J27="🟠 HAMPIR HABIS","Cek & Restock","")) -> SEGERA RESTOCK!
A28: 22 | B28: Plastik 24 | C28: 1 | D28: 1 | E28: pax | F28: =C28+D28 -> 2 | G28: 1 | H28: 1 Pack | I28: ='⚙️ Master Threshold'!E27 -> 1 | J28: =IF(I28=0,"—",IF(F28<=I28,"🔴 KRITIS",IF(F28<=I28*2,"🟠 HAMPIR HABIS","🟢 AMAN"))) -> 🟠 HAMPIR HABIS | L28: =IF(J28="🔴 KRITIS",B28,"") | M28: =IF(J28="🔴 KRITIS","SEGERA RESTOCK!",IF(J28="🟠 HAMPIR HABIS","Cek & Restock","")) -> Cek & Restock
A29: 23 | B29: Plastik 30 | C29: 1 | D29: 1 | E29: pax | F29: =C29+D29 -> 2 | G29: 1 | H29: 1 Pack | I29: ='⚙️ Master Threshold'!E28 -> 1 | J29: =IF(I29=0,"—",IF(F29<=I29,"🔴 KRITIS",IF(F29<=I29*2,"🟠 HAMPIR HABIS","🟢 AMAN"))) -> 🟠 HAMPIR HABIS | L29: =IF(J29="🔴 KRITIS",B29,"") | M29: =IF(J29="🔴 KRITIS","SEGERA RESTOCK!",IF(J29="🟠 HAMPIR HABIS","Cek & Restock","")) -> Cek & Restock
A30: 24 | B30: Kaldu Odeng | C30: 0 | D30: 301 | E30: gr | F30: =C30+D30 -> 301 | G30: 200 | H30: 1 Pack = 200 gr | I30: ='⚙️ Master Threshold'!E29 -> 100 | J30: =IF(I30=0,"—",IF(F30<=I30,"🔴 KRITIS",IF(F30<=I30*2,"🟠 HAMPIR HABIS","🟢 AMAN"))) -> 🟢 AMAN | L30: =IF(J30="🔴 KRITIS",B30,"") | M30: =IF(J30="🔴 KRITIS","SEGERA RESTOCK!",IF(J30="🟠 HAMPIR HABIS","Cek & Restock",""))
A31: 25 | B31: Baking Soda | C31: 0 | D31: 44 | E31: gr | F31: =C31+D31 -> 44 | G31: 80 | H31: 1 Botol = 80 gr | I31: ='⚙️ Master Threshold'!E30 -> 0 | J31: =IF(I31=0,"—",IF(F31<=I31,"🔴 KRITIS",IF(F31<=I31*2,"🟠 HAMPIR HABIS","🟢 AMAN"))) -> — | L31: =IF(J31="🔴 KRITIS",B31,"") | M31: =IF(J31="🔴 KRITIS","SEGERA RESTOCK!",IF(J31="🟠 HAMPIR HABIS","Cek & Restock",""))
A32: 26 | B32: Teh Tong Ji | C32: 0 | D32: 19 | E32: pcs | F32: =C32+D32 -> 19 | G32: 1 | H32: 1 Pack | I32: ='⚙️ Master Threshold'!E31 -> 3 | J32: =IF(I32=0,"—",IF(F32<=I32,"🔴 KRITIS",IF(F32<=I32*2,"🟠 HAMPIR HABIS","🟢 AMAN"))) -> 🟢 AMAN | L32: =IF(J32="🔴 KRITIS",B32,"") | M32: =IF(J32="🔴 KRITIS","SEGERA RESTOCK!",IF(J32="🟠 HAMPIR HABIS","Cek & Restock",""))
A33: 27 | B33: Dus Hampers | C33: 0 | D33: 1 | E33: pcs | F33: =C33+D33 -> 1 | G33: 100 | H33: 1 Pack = 100 pcs | I33: ='⚙️ Master Threshold'!E32 -> 0 | J33: =IF(I33=0,"—",IF(F33<=I33,"🔴 KRITIS",IF(F33<=I33*2,"🟠 HAMPIR HABIS","🟢 AMAN"))) -> — | L33: =IF(J33="🔴 KRITIS",B33,"") | M33: =IF(J33="🔴 KRITIS","SEGERA RESTOCK!",IF(J33="🟠 HAMPIR HABIS","Cek & Restock",""))
A34: 28 | B34: Box Berbagi | C34: 0 | D34: 0 | E34: pcs | F34: =C34+D34 -> 0 | G34: 50 | H34: 1 Pack = 50/100 pcs | I34: ='⚙️ Master Threshold'!E33 -> 0 | J34: =IF(I34=0,"—",IF(F34<=I34,"🔴 KRITIS",IF(F34<=I34*2,"🟠 HAMPIR HABIS","🟢 AMAN"))) -> — | L34: =IF(J34="🔴 KRITIS",B34,"") | M34: =IF(J34="🔴 KRITIS","SEGERA RESTOCK!",IF(J34="🟠 HAMPIR HABIS","Cek & Restock",""))
A35: 29 | B35: Botol Hampers | C35: 0 | D35: 3 | E35: pcs | F35: =C35+D35 -> 3 | G35: 25 | H35: 1 Pack = 25 pcs | I35: ='⚙️ Master Threshold'!E34 -> 0 | J35: =IF(I35=0,"—",IF(F35<=I35,"🔴 KRITIS",IF(F35<=I35*2,"🟠 HAMPIR HABIS","🟢 AMAN"))) -> — | L35: =IF(J35="🔴 KRITIS",B35,"") | M35: =IF(J35="🔴 KRITIS","SEGERA RESTOCK!",IF(J35="🟠 HAMPIR HABIS","Cek & Restock",""))
A36: 30 | B36: Gas Torch | C36: 0 | D36: 206 | E36: gr | F36: =C36+D36-110 -> 96 | H36: — | I36: ='⚙️ Master Threshold'!E35 -> 100 | J36: =IF(I36=0,"—",IF(F36<=I36,"🔴 KRITIS",IF(F36<=I36*2,"🟠 HAMPIR HABIS","🟢 AMAN"))) -> 🔴 KRITIS | L36: =IF(J36="🔴 KRITIS",B36,"") -> Gas Torch | M36: =IF(J36="🔴 KRITIS","SEGERA RESTOCK!",IF(J36="🟠 HAMPIR HABIS","Cek & Restock","")) -> SEGERA RESTOCK!
A37: 31 | B37: Katsubuoshi | C37: 0 | D37: 33 | E37: gr | F37: =C37+D37 -> 33 | G37: 50 | H37: 1 Pack = 50 gr | I37: ='⚙️ Master Threshold'!E36 -> 5 | J37: =IF(I37=0,"—",IF(F37<=I37,"🔴 KRITIS",IF(F37<=I37*2,"🟠 HAMPIR HABIS","🟢 AMAN"))) -> 🟢 AMAN | L37: =IF(J37="🔴 KRITIS",B37,"") | M37: =IF(J37="🔴 KRITIS","SEGERA RESTOCK!",IF(J37="🟠 HAMPIR HABIS","Cek & Restock",""))
A38: 32 | B38: Spray Lemon Pepper | C38: 0 | D38: 63 | E38: gr | F38: =C38+D38 -> 63 | I38: ='⚙️ Master Threshold'!E37 -> 40 | J38: =IF(I38=0,"—",IF(F38<=I38,"🔴 KRITIS",IF(F38<=I38*2,"🟠 HAMPIR HABIS","🟢 AMAN"))) -> 🟠 HAMPIR HABIS
A39: 33 | B39: Lemon Papper | C39: 0 | D39: 322 | E39: gr | F39: =C39+D39-42 -> 280 | I39: ='⚙️ Master Threshold'!E38 -> 100 | J39: =IF(I39=0,"—",IF(F39<=I39,"🔴 KRITIS",IF(F39<=I39*2,"🟠 HAMPIR HABIS","🟢 AMAN"))) -> 🟢 AMAN
A40: ▶ CHILLER
A41: 1 | B41: Ultra (susu) | C41: 1000 | D41: 524 | E41: gr | F41: =C41+D41 -> 1524 | G41: 1000 | H41: 1 Dus = 1000 ml | I41: ='⚙️ Master Threshold'!E39 -> 250 | J41: =IF(I41=0,"—",IF(F41<=I41,"🔴 KRITIS",IF(F41<=I41*2,"🟠 HAMPIR HABIS","🟢 AMAN"))) -> 🟢 AMAN | L41: =IF(J41="🔴 KRITIS",B41,"") | M41: =IF(J41="🔴 KRITIS","SEGERA RESTOCK!",IF(J41="🟠 HAMPIR HABIS","Cek & Restock",""))
...

Sheet Freezer & Alat
A1: 📋 STOK OPNAME HARIAN — FREEZER, AYAM & ALAT
A2: TANGGAL / HARI | C2: 46257 | E2: HARI | G2: =TEXT(C2,"DDDD") -> Sunday | I2: NAMA PETUGAS | K2: Candra
A3: KETERANGAN WARNA STATUS: 🔴 STOK HABIS / KRITIS 🟠 STOK HAMPIR HABIS (< 2× Threshold) 🟢 STOK AMAN
A5: No | B5: NAMA BARANG | C5: STEP 1 HITUNG UTUH (Qty) | D5: STEP 2 HITUNG TERBUKA (Qty) | E5: SATUAN | F5: TOTAL (Step1 + Step2) | G5: KONVERSI (Isi per Pack) | H5: KONVERSI (Keterangan) | I5: MIN THRESHOLD | J5: STATUS STOK | L5: REQUEST BARANG HABIS / KRITIS | M5: QTY Request
A6: 4.8
A7: 1 | B7: Wings Baru | C7: 5 | D7: 0 | E7: kg | F7: =C7+D7 -> 5 | H7: — | I7: ='⚙️ Master Threshold'!E66 -> 2 | J7: =IF(I7=0,"—",IF(F7<=I7,"🔴 KRITIS",IF(F7<=I7*2,"🟠 HAMPIR HABIS","🟢 AMAN"))) -> 🟢 AMAN | L7: =IF(J7="🔴 KRITIS",B7,"") | M7: =IF(J7="🔴 KRITIS","SEGERA RESTOCK!",IF(J7="🟠 HAMPIR HABIS","Cek & Restock",""))
A8: 2 | B8: Wings Lama | C8: 0 | D8: 2 | E8: kg | F8: =C8+D8 -> 2 | H8: — | I8: ='⚙️ Master Threshold'!E67 -> 1 | J8: =IF(I8=0,"—",IF(F8<=I8,"🔴 KRITIS",IF(F8<=I8*2,"🟠 HAMPIR HABIS","🟢 AMAN"))) -> 🟠 HAMPIR HABIS | L8: =IF(J8="🔴 KRITIS",B8,"") | M8: =IF(J8="🔴 KRITIS","SEGERA RESTOCK!",IF(J8="🟠 HAMPIR HABIS","Cek & Restock","")) -> Cek & Restock
A9: 3 | B9: Pop (baru) | C9: 5 | D9: 3.7 | E9: kg | F9: =C9+D9 -> 8.7 | H9: — | I9: ='⚙️ Master Threshold'!E68 -> 2 | J9: =IF(I9=0,"—",IF(F9<=I9,"🔴 KRITIS",IF(F9<=I9*2,"🟠 HAMPIR HABIS","🟢 AMAN"))) -> 🟢 AMAN | L9: =IF(J9="🔴 KRITIS",B9,"") | M9: =IF(J9="🔴 KRITIS","SEGERA RESTOCK!",IF(J9="🟠 HAMPIR HABIS","Cek & Restock",""))
A10: 4 | B10: Pop (lama) | C10: 0 | D10: 2.4 | E10: kg | F10: =C10+D10 -> 2.4 | H10: — | I10: ='⚙️ Master Threshold'!E69 -> 1 | J10: =IF(I10=0,"—",IF(F10<=I10,"🔴 KRITIS",IF(F10<=I10*2,"🟠 HAMPIR HABIS","🟢 AMAN"))) -> 🟢 AMAN | L10: =IF(J10="🔴 KRITIS",B10,"") | M10: =IF(J10="🔴 KRITIS","SEGERA RESTOCK!",IF(J10="🟠 HAMPIR HABIS","Cek & Restock",""))
A11: 5 | B11: Ayam Ekor | C11: 0 | D11: 0 | E11: pcs | F11: =C11+D11 -> 0 | H11: — | I11: ='⚙️ Master Threshold'!E70 -> 5 | J11: =IF(I11=0,"—",IF(F11<=I11,"🔴 KRITIS",IF(F11<=I11*2,"🟠 HAMPIR HABIS","🟢 AMAN"))) -> 🔴 KRITIS | L11: =IF(J11="🔴 KRITIS",B11,"") -> Ayam Ekor | M11: =IF(J11="🔴 KRITIS","SEGERA RESTOCK!",IF(J11="🟠 HAMPIR HABIS","Cek & Restock","")) -> SEGERA RESTOCK!
A12: 6 | B12: Reguler Lama | C12: 0 | D12: 0 | E12: kg | F12: =C12+D12 -> 0 | H12: — | I12: ='⚙️ Master Threshold'!E71 -> 2 | J12: =IF(I12=0,"—",IF(F12<=I12,"🔴 KRITIS",IF(F12<=I12*2,"🟠 HAMPIR HABIS","🟢 AMAN"))) -> 🔴 KRITIS | L12: =IF(J12="🔴 KRITIS",B12,"") -> Reguler Lama | M12: =IF(J12="🔴 KRITIS","SEGERA RESTOCK!",IF(J12="🟠 HAMPIR HABIS","Cek & Restock","")) -> SEGERA RESTOCK!
A13: 7 | B13: Reguler Baru | C13: 0 | D13: 0 | E13: kg | F13: =C13+D13 -> 0 | H13: — | I13: ='⚙️ Master Threshold'!E72 -> 2 | J13: =IF(I13=0,"—",IF(F13<=I13,"🔴 KRITIS",IF(F13<=I13*2,"🟠 HAMPIR HABIS","🟢 AMAN"))) -> 🔴 KRITIS | L13: =IF(J13="🔴 KRITIS",B13,"") -> Reguler Baru | M13: =IF(J13="🔴 KRITIS","SEGERA RESTOCK!",IF(J13="🟠 HAMPIR HABIS","Cek & Restock","")) -> SEGERA RESTOCK!
A14: 8 | B14: Es Batu | C14: 1 | D14: 0.4 | E14: bungkus -+ | F14: =C14+D14 -> 12/31 | H14: — | I14: ='⚙️ Master Threshold'!E73 -> 0.5 | J14: =IF(I14=0,"—",IF(F14<=I14,"🔴 KRITIS",IF(F14<=I14*2,"🟠 HAMPIR HABIS","🟢 AMAN"))) -> 🟢 AMAN | L14: =IF(J14="🔴 KRITIS",B14,"") | M14: =IF(J14="🔴 KRITIS","SEGERA RESTOCK!",IF(J14="🟠 HAMPIR HABIS","Cek & Restock",""))
A15: 9 | B15: Kentang | C15: 1 | D15: 11 | E15: pcs | F15: =C15+D15 -> 12 | H15: — | I15: ='⚙️ Master Threshold'!E74 -> 3 | J15: =IF(I15=0,"—",IF(F15<=I15,"🔴 KRITIS",IF(F15<=I15*2,"🟠 HAMPIR HABIS","🟢 AMAN"))) -> 🟢 AMAN | L15: =IF(J15="🔴 KRITIS",B15,"") | M15: =IF(J15="🔴 KRITIS","SEGERA RESTOCK!",IF(J15="🟠 HAMPIR HABIS","Cek & Restock",""))
A16: 10 | B16: Corndog Moza+Sosis | C16: 0 | D16: 2 | E16: pcs | F16: =C16+D16 -> 2 | H16: — | I16: ='⚙️ Master Threshold'!E75 -> 3 | J16: =IF(I16=0,"—",IF(F16<=I16,"🔴 KRITIS",IF(F16<=I16*2,"🟠 HAMPIR HABIS","🟢 AMAN"))) -> 🔴 KRITIS | L16: =IF(J16="🔴 KRITIS",B16,"") -> Corndog Moza+Sosis | M16: =IF(J16="🔴 KRITIS","SEGERA RESTOCK!",IF(J16="🟠 HAMPIR HABIS","Cek & Restock","")) -> SEGERA RESTOCK!
A17: 11 | B17: Corndog Sosis | C17: 0 | D17: 4 | E17: pcs | F17: =C17+D17 -> 4 | H17: — | I17: ='⚙️ Master Threshold'!E76 -> 3 | J17: =IF(I17=0,"—",IF(F17<=I17,"🔴 KRITIS",IF(F17<=I17*2,"🟠 HAMPIR HABIS","🟢 AMAN"))) -> 🟠 HAMPIR HABIS | L17: =IF(J17="🔴 KRITIS",B17,"") | M17: =IF(J17="🔴 KRITIS","SEGERA RESTOCK!",IF(J17="🟠 HAMPIR HABIS","Cek & Restock","")) -> Cek & Restock
A18: 12 | B18: Odeng (porsi) | C18: 0 | D18: 0 | E18: porsi | F18: =C18+D18 -> 0 | G18: 2 | H18: 2 lembar = 1 porsi | I18: ='⚙️ Master Threshold'!E77 -> 5 | J18: =IF(I18=0,"—",IF(F18<=I18,"🔴 KRITIS",IF(F18<=I18*2,"🟠 HAMPIR HABIS","🟢 AMAN"))) -> 🔴 KRITIS | L18: =IF(J18="🔴 KRITIS",B18,"") -> Odeng (porsi) | M18: =IF(J18="🔴 KRITIS","SEGERA RESTOCK!",IF(J18="🟠 HAMPIR HABIS","Cek & Restock","")) -> SEGERA RESTOCK!
A19: 13 | B19: Baso Ikan | C19: 15 | D19: 1 | E19: pcs | F19: =C19+D19 -> 16 | H19: — | I19: ='⚙️ Master Threshold'!E78 -> 5 | J19: =IF(I19=0,"—",IF(F19<=I19,"🔴 KRITIS",IF(F19<=I19*2,"🟠 HAMPIR HABIS","🟢 AMAN"))) -> 🟢 AMAN | L19: =IF(J19="🔴 KRITIS",B19,"") | M19: =IF(J19="🔴 KRITIS","SEGERA RESTOCK!",IF(J19="🟠 HAMPIR HABIS","Cek & Restock",""))
A20: 14 | B20: Potato Cheese Ball | C20: =(8*6)+5 -> 53 | D20: 14 | E20: pcs | F20: =C20+D20 -> 67 | H20: — | I20: ='⚙️ Master Threshold'!E79 -> 5 | J20: =IF(I20=0,"—",IF(F20<=I20,"🔴 KRITIS",IF(F20<=I20*2,"🟠 HAMPIR HABIS","🟢 AMAN"))) -> 🟢 AMAN | L20: =IF(J20="🔴 KRITIS",B20,"") | M20: =IF(J20="🔴 KRITIS","SEGERA RESTOCK!",IF(J20="🟠 HAMPIR HABIS","Cek & Restock",""))
A21: 15 | B21: Dumpling | C21: 12 | D21: 7 | E21: pcs | F21: =C21+D21 -> 19 | H21: — | I21: ='⚙️ Master Threshold'!E80 -> 5 | J21: =IF(I21=0,"—",IF(F21<=I21,"🔴 KRITIS",IF(F21<=I21*2,"🟠 HAMPIR HABIS","🟢 AMAN"))) -> 🟢 AMAN | L21: =IF(J21="🔴 KRITIS",B21,"") | M21: =IF(J21="🔴 KRITIS","SEGERA RESTOCK!",IF(J21="🟠 HAMPIR HABIS","Cek & Restock",""))
A22: 16 | B22: Dimsum Mix | C22: 12 | D22: 0 | E22: pax | F22: =C22+D22 -> 12 | G22: 30 | H22: 1 pax = 30 pcs | I22: ='⚙️ Master Threshold'!E81 -> 1 | J22: =IF(I22=0,"—",IF(F22<=I22,"🔴 KRITIS",IF(F22<=I22*2,"🟠 HAMPIR HABIS","🟢 AMAN"))) -> 🟢 AMAN | L22: =IF(J22="🔴 KRITIS",B22,"") | M22: =IF(J22="🔴 KRITIS","SEGERA RESTOCK!",IF(J22="🟠 HAMPIR HABIS","Cek & Restock",""))
A23: 17 | B23: Ayam Katsu | C23: 0 | D23: 0 | E23: pcs | F23: =C23+D23 -> 0 | H23: — | I23: ='⚙️ Master Threshold'!E82 -> 5 | J23: =IF(I23=0,"—",IF(F23<=I23,"🔴 KRITIS",IF(F23<=I23*2,"🟠 HAMPIR HABIS","🟢 AMAN"))) -> 🔴 KRITIS | L23: =IF(J23="🔴 KRITIS",B23,"") -> Ayam Katsu | M23: =IF(J23="🔴 KRITIS","SEGERA RESTOCK!",IF(J23="🟠 HAMPIR HABIS","Cek & Restock","")) -> SEGERA RESTOCK!
A24: ▶ BARANG ALAT & KEBERSIHAN
A25: 1 | B25: Cling Pembersih | C25: 0 | D25: 0.4 | E25: botol -+ | F25: =C25+D25 -> 0.4 | H25: — | I25: ='⚙️ Master Threshold'!E83 -> 1 | J25: =IF(I25=0,"—",IF(F25<=I25,"🔴 KRITIS",IF(F25<=I25*2,"🟠 HAMPIR HABIS","🟢 AMAN"))) -> 🔴 KRITIS | L25: =IF(J25="🔴 KRITIS",B25,"") -> Cling Pembersih | M25: =IF(J25="🔴 KRITIS","SEGERA RESTOCK!",IF(J25="🟠 HAMPIR HABIS","Cek & Restock","")) -> SEGERA RESTOCK!
A26: 2 | B26: Sabun Cuci Piring | C26: 0 | D26: 0.4 | E26: pax -+ | F26: =C26+D26 -> 0.4 | H26: — | I26: ='⚙️ Master Threshold'!E84 -> 1 | J26: =IF(I26=0,"—",IF(F26<=I26,"🔴 KRITIS",IF(F26<=I26*2,"🟠 HAMPIR HABIS","🟢 AMAN"))) -> 🔴 KRITIS | L26: =IF(J26="🔴 KRITIS",B26,"") -> Sabun Cuci Piring | M26: =IF(J26="🔴 KRITIS","SEGERA RESTOCK!",IF(J26="🟠 HAMPIR HABIS","Cek & Restock","")) -> SEGERA RESTOCK!
A27: 3 | B27: S.O.S Karbol | C27: 0 | D27: 0.3 | E27: pax -+ | F27: =C27+D27 -> 0.3 | H27: — | I27: ='⚙️ Master Threshold'!E85 -> 1 | J27: =IF(I27=0,"—",IF(F27<=I27,"🔴 KRITIS",IF(F27<=I27*2,"🟠 HAMPIR HABIS","🟢 AMAN"))) -> 🔴 KRITIS | L27: =IF(J27="🔴 KRITIS",B27,"") -> S.O.S Karbol | M27: =IF(J27="🔴 KRITIS","SEGERA RESTOCK!",IF(J27="🟠 HAMPIR HABIS","Cek & Restock","")) -> SEGERA RESTOCK!
A28: 4 | B28: Vixal | C28: 0 | D28: 0 | E28: botol | F28: =C28+D28 -> 0 | H28: — | I28: ='⚙️ Master Threshold'!E86 -> 1 | J28: =IF(I28=0,"—",IF(F28<=I28,"🔴 KRITIS",IF(F28<=I28*2,"🟠 HAMPIR HABIS","🟢 AMAN"))) -> 🔴 KRITIS | L28: =IF(J28="🔴 KRITIS",B28,"") -> Vixal | M28: =IF(J28="🔴 KRITIS","SEGERA RESTOCK!",IF(J28="🟠 HAMPIR HABIS","Cek & Restock","")) -> SEGERA RESTOCK!
A29: 5 | B29: Sendok | C29: 0 | D29: 0 | E29: pcs | F29: =C29+D29 -> 0 | H29: — | I29: ='⚙️ Master Threshold'!E87 -> 5 | J29: =IF(I29=0,"—",IF(F29<=I29,"🔴 KRITIS",IF(F29<=I29*2,"🟠 HAMPIR HABIS","🟢 AMAN"))) -> 🔴 KRITIS | L29: =IF(J29="🔴 KRITIS",B29,"") -> Sendok | M29: =IF(J29="🔴 KRITIS","SEGERA RESTOCK!",IF(J29="🟠 HAMPIR HABIS","Cek & Restock","")) -> SEGERA RESTOCK!
A30: 6 | B30: Mangkuk Stainless | C30: 0 | D30: 11 | E30: pcs | F30: =C30+D30 -> 11 | H30: — | I30: ='⚙️ Master Threshold'!E88 -> 3 | J30: =IF(I30=0,"—",IF(F30<=I30,"🔴 KRITIS",IF(F30<=I30*2,"🟠 HAMPIR HABIS","🟢 AMAN"))) -> 🟢 AMAN | L30: =IF(J30="🔴 KRITIS",B30,"") | M30: =IF(J30="🔴 KRITIS","SEGERA RESTOCK!",IF(J30="🟠 HAMPIR HABIS","Cek & Restock",""))
A31: 7 | B31: Piring Stainless | C31: 0 | D31: 2 | E31: pcs | F31: =C31+D31 -> 2 | H31: — | I31: ='⚙️ Master Threshold'!E89 -> 3 | J31: =IF(I31=0,"—",IF(F31<=I31,"🔴 KRITIS",IF(F31<=I31*2,"🟠 HAMPIR HABIS","🟢 AMAN"))) -> 🔴 KRITIS | L31: =IF(J31="🔴 KRITIS",B31,"") -> Piring Stainless | M31: =IF(J31="🔴 KRITIS","SEGERA RESTOCK!",IF(J31="🟠 HAMPIR HABIS","Cek & Restock","")) -> SEGERA RESTOCK!
A32: 8 | B32: Piring Plastik | C32: 0 | D32: 3 | E32: pcs | F32: =C32+D32 -> 3 | H32: — | I32: ='⚙️ Master Threshold'!E90 -> 3 | J32: =IF(I32=0,"—",IF(F32<=I32,"🔴 KRITIS",IF(F32<=I32*2,"🟠 HAMPIR HABIS","🟢 AMAN"))) -> 🔴 KRITIS | L32: =IF(J32="🔴 KRITIS",B32,"") -> Piring Plastik | M32: =IF(J32="🔴 KRITIS","SEGERA RESTOCK!",IF(J32="🟠 HAMPIR HABIS","Cek & Restock","")) -> SEGERA RESTOCK!
A33: 9 | B33: Keranjang Kotak Hitam Besi | C33: 0 | D33: 2 | E33: pcs | F33: =C33+D33 -> 2 | H33: — | I33: ='⚙️ Master Threshold'!E91 -> 2 | J33: =IF(I33=0,"—",IF(F33<=I33,"🔴 KRITIS",IF(F33<=I33*2,"🟠 HAMPIR HABIS","🟢 AMAN"))) -> 🔴 KRITIS | L33: =IF(J33="🔴 KRITIS",B33,"") -> Keranjang Kotak Hitam Besi | M33: =IF(J33="🔴 KRITIS","SEGERA RESTOCK!",IF(J33="🟠 HAMPIR HABIS","Cek & Restock","")) -> SEGERA RESTOCK!
A34: 10 | B34: Keranjang Bulat Hitam Besi | C34: 0 | D34: 1 | E34: pcs | F34: =C34+D34 -> 1 | H34: — | I34: ='⚙️ Master Threshold'!E92 -> 2 | J34: =IF(I34=0,"—",IF(F34<=I34,"🔴 KRITIS",IF(F34<=I34*2,"🟠 HAMPIR HABIS","🟢 AMAN"))) -> 🔴 KRITIS | L34: =IF(J34="🔴 KRITIS",B34,"") -> Keranjang Bulat Hitam Besi | M34: =IF(J34="🔴 KRITIS","SEGERA RESTOCK!",IF(J34="🟠 HAMPIR HABIS","Cek & Restock","")) -> SEGERA RESTOCK!
A35: 11 | B35: Keranjang Merah Plastik | C35: 0 | D35: 5 | E35: pcs | F35: =C35+D35 -> 5 | H35: — | I35: ='⚙️ Master Threshold'!E93 -> 2 | J35: =IF(I35=0,"—",IF(F35<=I35,"🔴 KRITIS",IF(F35<=I35*2,"🟠 HAMPIR HABIS","🟢 AMAN"))) -> 🟢 AMAN | L35: =IF(J35="🔴 KRITIS",B35,"") | M35: =IF(J35="🔴 KRITIS","SEGERA RESTOCK!",IF(J35="🟠 HAMPIR HABIS","Cek & Restock",""))
A36: 12 | B36: Keranjang Hitam Plastik | C36: 0 | D36: 3 | E36: pcs | F36: =C36+D36 -> 3 | H36: — | I36: ='⚙️ Master Threshold'!E94 -> 2 | J36: =IF(I36=0,"—",IF(F36<=I36,"🔴 KRITIS",IF(F36<=I36*2,"🟠 HAMPIR HABIS","🟢 AMAN"))) -> 🟠 HAMPIR HABIS | L36: =IF(J36="🔴 KRITIS",B36,"") | M36: =IF(J36="🔴 KRITIS","SEGERA RESTOCK!",IF(J36="🟠 HAMPIR HABIS","Cek & Restock","")) -> Cek & Restock
A37: 13 | B37: Gelas Customer | C37: 0 | D37: 8 | E37: pcs | F37: =C37+D37 -> 8 | H37: — | I37: ='⚙️ Master Threshold'!E95 -> 5 | J37: =IF(I37=0,"—",IF(F37<=I37,"🔴 KRITIS",IF(F37<=I37*2,"🟠 HAMPIR HABIS","🟢 AMAN"))) -> 🟠 HAMPIR HABIS | L37: =IF(J37="🔴 KRITIS",B37,"") | M37: =IF(J37="🔴 KRITIS","SEGERA RESTOCK!",IF(J37="🟠 HAMPIR HABIS","Cek & Restock","")) -> Cek & Restock
A38: TOTAL ITEM DICEK | F38: =COUNTA(B6:B37)-COUNTIF(B6:B37,"") -> 28 | G38: ITEM KRITIS: | J38: =COUNTIF(J6:J37,"🔴 KRITIS") -> 15 | K38: =COUNTIF(J6:J37,"🟠 HAMPIR HABIS")&" item hampir habis" -> 4 item hampir habis

Sheet Meja Laci (2)
A1: 📋 STOK OPNAME HARIAN — MEJA LACI
A2: TANGGAL / HARI | C2: 46257 | E2: HARI | G2: =TEXT(C2,"DDDD") -> Sunday | I2: NAMA PETUGAS | K2: Candra
A3: KETERANGAN WARNA STATUS: 🔴 STOK HABIS / KRITIS 🟠 STOK HAMPIR HABIS (< 2× Threshold) 🟢 STOK AMANf
A5: No | B5: NAMA BARANG | C5: STEP 1 HITUNG UTUH (Qty) | D5: STEP 2 HITUNG TERBUKA (Qty) | E5: SATUAN | F5: TOTAL (Step1 + Step2) | G5: KONVERSI (Isi per Pack) | H5: KONVERSI (Keterangan) | I5: MIN THRESHOLD | J5: STATUS STOK | L5: REQUEST BARANG HABIS / KRITIS | M5: QTY Request
A6: ▶ PACKAGING & PERLENGKAPAN OPERASIONAL
A7: 1 | B7: Sticker Thinwal | C7: 0 | D7: 1 | E7: pcs -+ | F7: =C7+D7 -> 1 | H7: — | I7: ='⚙️ Master Threshold'!E97 -> 10 | J7: =IF(I7=0,"—",IF(F7<=I7,"🔴 KRITIS",IF(F7<=I7*2,"🟠 HAMPIR HABIS","🟢 AMAN"))) -> 🔴 KRITIS | L7: =IF(J7="🔴 KRITIS",B7,"") -> Sticker Thinwal | M7: =IF(J7="🔴 KRITIS","SEGERA RESTOCK!",IF(J7="🟠 HAMPIR HABIS","Cek & Restock","")) -> SEGERA RESTOCK!
A8: 2 | B8: Solasi Bening | C8: 4 | D8: 1 | E8: pcs -+ | F8: =C8+D8 -> 5 | H8: — | I8: ='⚙️ Master Threshold'!E98 -> 1 | J8: =IF(I8=0,"—",IF(F8<=I8,"🔴 KRITIS",IF(F8<=I8*2,"🟠 HAMPIR HABIS","🟢 AMAN"))) -> 🟢 AMAN | L8: =IF(J8="🔴 KRITIS",B8,"") | M8: =IF(J8="🔴 KRITIS","SEGERA RESTOCK!",IF(J8="🟠 HAMPIR HABIS","Cek & Restock",""))
A9: 3 | B9: Cable Ties | C9: 2 | D9: 1 | E9: pax | F9: =C9+D9 -> 3 | H9: — | I9: ='⚙️ Master Threshold'!E99 -> 1 | J9: =IF(I9=0,"—",IF(F9<=I9,"🔴 KRITIS",IF(F9<=I9*2,"🟠 HAMPIR HABIS","🟢 AMAN"))) -> 🟢 AMAN | L9: =IF(J9="🔴 KRITIS",B9,"") | M9: =IF(J9="🔴 KRITIS","SEGERA RESTOCK!",IF(J9="🟠 HAMPIR HABIS","Cek & Restock",""))
A10: 4 | B10: Sticky Note | C10: 1 | D10: 1 | E10: pax | F10: =C10+D10 -> 2 | H10: — | I10: ='⚙️ Master Threshold'!E100 -> 1 | J10: =IF(I10=0,"—",IF(F10<=I10,"🔴 KRITIS",IF(F10<=I10*2,"🟠 HAMPIR HABIS","🟢 AMAN"))) -> 🟠 HAMPIR HABIS | L10: =IF(J10="🔴 KRITIS",B10,"") | M10: =IF(J10="🔴 KRITIS","SEGERA RESTOCK!",IF(J10="🟠 HAMPIR HABIS","Cek & Restock","")) -> Cek & Restock
A11: 5 | B11: Dus Drakor Stock | C11: 400 | D11: 20 | E11: pcs -+ | F11: =C11+D11 -> 420 | H11: — | I11: ='⚙️ Master Threshold'!E101 -> 5 | J11: =IF(I11=0,"—",IF(F11<=I11,"🔴 KRITIS",IF(F11<=I11*2,"🟠 HAMPIR HABIS","🟢 AMAN"))) -> 🟢 AMAN | L11: =IF(J11="🔴 KRITIS",B11,"") | M11: =IF(J11="🔴 KRITIS","SEGERA RESTOCK!",IF(J11="🟠 HAMPIR HABIS","Cek & Restock",""))
A12: =A11+1 -> 6 | B12: Dus Rice Box | C12: 450 | D12: 10 | E12: -+ pcs | F12: =C12+D12 -> 460 | I12: ='⚙️ Master Threshold'!E102 -> 50 | J12: =IF(I12=0,"—",IF(F12<=I12,"🔴 KRITIS",IF(F12<=I12*2,"🟠 HAMPIR HABIS","🟢 AMAN"))) -> 🟢 AMAN | L12: =IF(J12="🔴 KRITIS",B12,"") | M12: =IF(J12="🔴 KRITIS","SEGERA RESTOCK!",IF(J12="🟠 HAMPIR HABIS","Cek & Restock",""))
A13: =A12+1 -> 7 | B13: Kartu Nama | C13: 1000 | D13: 0 | E13: pcs | F13: =C13+D13 -> 1000 | H13: — | I13: ='⚙️ Master Threshold'!E103 -> 10 | J13: =IF(I13=0,"—",IF(F13<=I13,"🔴 KRITIS",IF(F13<=I13*2,"🟠 HAMPIR HABIS","🟢 AMAN"))) -> 🟢 AMAN | L13: =IF(J13="🔴 KRITIS",B13,"") | M13: =IF(J13="🔴 KRITIS","SEGERA RESTOCK!",IF(J13="🟠 HAMPIR HABIS","Cek & Restock",""))
A14: =A13+1 -> 8 | B14: Kertas Struk EDC | C14: 14 | D14: 2 | E14: pcs | F14: =C14+D14 -> 16 | H14: — | I14: ='⚙️ Master Threshold'!E104 -> 1 | J14: =IF(I14=0,"—",IF(F14<=I14,"🔴 KRITIS",IF(F14<=I14*2,"🟠 HAMPIR HABIS","🟢 AMAN"))) -> 🟢 AMAN | L14: =IF(J14="🔴 KRITIS",B14,"") | M14: =IF(J14="🔴 KRITIS","SEGERA RESTOCK!",IF(J14="🟠 HAMPIR HABIS","Cek & Restock",""))
A15: =A14+1 -> 9 | B15: Sumpit | C15: 50 | D15: 8 | E15: pcs -+ | F15: =C15+D15 -> 58 | H15: — | I15: ='⚙️ Master Threshold'!E105 -> 50 | J15: =IF(I15=0,"—",IF(F15<=I15,"🔴 KRITIS",IF(F15<=I15*2,"🟠 HAMPIR HABIS","🟢 AMAN"))) -> 🟠 HAMPIR HABIS | L15: =IF(J15="🔴 KRITIS",B15,"") | M15: =IF(J15="🔴 KRITIS","SEGERA RESTOCK!",IF(J15="🟠 HAMPIR HABIS","Cek & Restock","")) -> Cek & Restock
A16: =A15+1 -> 10 | B16: Tusuk Odeng | C16: 0 | D16: 0 | E16: pcs -+ | F16: =C16+D16 -> 0 | H16: — | I16: ='⚙️ Master Threshold'!E106 -> 20 | J16: =IF(I16=0,"—",IF(F16<=I16,"🔴 KRITIS",IF(F16<=I16*2,"🟠 HAMPIR HABIS","🟢 AMAN"))) -> 🔴 KRITIS | L16: =IF(J16="🔴 KRITIS",B16,"") -> Tusuk Odeng | M16: =IF(J16="🔴 KRITIS","SEGERA RESTOCK!",IF(J16="🟠 HAMPIR HABIS","Cek & Restock","")) -> SEGERA RESTOCK!
A17: =A16+1 -> 11 | B17: Sendok | C17: 50 | D17: 48 | E17: pcs -+ | F17: =C17+D17 -> 98 | H17: — | I17: ='⚙️ Master Threshold'!E107 -> 50 | J17: =IF(I17=0,"—",IF(F17<=I17,"🔴 KRITIS",IF(F17<=I17*2,"🟠 HAMPIR HABIS","🟢 AMAN"))) -> 🟠 HAMPIR HABIS | L17: =IF(J17="🔴 KRITIS",B17,"") | M17: =IF(J17="🔴 KRITIS","SEGERA RESTOCK!",IF(J17="🟠 HAMPIR HABIS","Cek & Restock","")) -> Cek & Restock
A18: =A17+1 -> 12 | B18: Sendok Kayu | C18: 0 | D18: 1 | E18: pax | F18: =C18+D18 -> 1 | H18: — | I18: ='⚙️ Master Threshold'!E108 -> 2 | J18: =IF(I18=0,"—",IF(F18<=I18,"🔴 KRITIS",IF(F18<=I18*2,"🟠 HAMPIR HABIS","🟢 AMAN"))) -> 🔴 KRITIS | L18: =IF(J18="🔴 KRITIS",B18,"") -> Sendok Kayu | M18: =IF(J18="🔴 KRITIS","SEGERA RESTOCK!",IF(J18="🟠 HAMPIR HABIS","Cek & Restock","")) -> SEGERA RESTOCK!
A19: =A18+1 -> 13 | B19: Plastik Kentang | C19: 8 | D19: 1 | E19: ikat/pack | F19: =C19+D19 -> 9 | H19: — | I19: ='⚙️ Master Threshold'!E109 -> 1 | J19: =IF(I19=0,"—",IF(F19<=I19,"🔴 KRITIS",IF(F19<=I19*2,"🟠 HAMPIR HABIS","🟢 AMAN"))) -> 🟢 AMAN | L19: =IF(J19="🔴 KRITIS",B19,"") | M19: =IF(J19="🔴 KRITIS","SEGERA RESTOCK!",IF(J19="🟠 HAMPIR HABIS","Cek & Restock",""))
A20: =A19+1 -> 14 | B20: Plastik Cetik | C20: 0 | D20: 2 | E20: pax | F20: =C20+D20 -> 2 | H20: — | I20: ='⚙️ Master Threshold'!E110 -> 1 | J20: =IF(I20=0,"—",IF(F20<=I20,"🔴 KRITIS",IF(F20<=I20*2,"🟠 HAMPIR HABIS","🟢 AMAN"))) -> 🟠 HAMPIR HABIS | L20: =IF(J20="🔴 KRITIS",B20,"") | M20: =IF(J20="🔴 KRITIS","SEGERA RESTOCK!",IF(J20="🟠 HAMPIR HABIS","Cek & Restock","")) -> Cek & Restock
A21: =A20+1 -> 15 | B21: Kertas Nasi Putih | C21: 1 | D21: 1 | E21: pax | F21: =C21+D21 -> 2 | H21: — | I21: ='⚙️ Master Threshold'!E111 -> 1 | J21: =IF(I21=0,"—",IF(F21<=I21,"🔴 KRITIS",IF(F21<=I21*2,"🟠 HAMPIR HABIS","🟢 AMAN"))) -> 🟠 HAMPIR HABIS | L21: =IF(J21="🔴 KRITIS",B21,"") | M21: =IF(J21="🔴 KRITIS","SEGERA RESTOCK!",IF(J21="🟠 HAMPIR HABIS","Cek & Restock","")) -> Cek & Restock
A22: =A21+1 -> 16 | B22: Label Biasa | C22: 0 | D22: 0 | E22: lembar | F22: =C22+D22 -> 0 | H22: — | I22: ='⚙️ Master Threshold'!E112 -> 20 | J22: =IF(I22=0,"—",IF(F22<=I22,"🔴 KRITIS",IF(F22<=I22*2,"🟠 HAMPIR HABIS","🟢 AMAN"))) -> 🔴 KRITIS | L22: =IF(J22="🔴 KRITIS",B22,"") -> Label Biasa | M22: =IF(J22="🔴 KRITIS","SEGERA RESTOCK!",IF(J22="🟠 HAMPIR HABIS","Cek & Restock","")) -> SEGERA RESTOCK!
A23: =A22+1 -> 17 | B23: Thinwal Biasa | C23: 0 | D23: 12 | E23: pax-pcs | F23: =C23+D23 -> 12 | H23: — | I23: ='⚙️ Master Threshold'!E113 -> 20 | J23: =IF(I23=0,"—",IF(F23<=I23,"🔴 KRITIS",IF(F23<=I23*2,"🟠 HAMPIR HABIS","🟢 AMAN"))) -> 🔴 KRITIS | L23: =IF(J23="🔴 KRITIS",B23,"") -> Thinwal Biasa | M23: =IF(J23="🔴 KRITIS","SEGERA RESTOCK!",IF(J23="🟠 HAMPIR HABIS","Cek & Restock","")) -> SEGERA RESTOCK!
A24: =A23+1 -> 18 | B24: Thinwal 1250 ml | C24: 0 | D24: 0 | E24: pax | F24: =C24+D24 -> 0 | H24: — | I24: ='⚙️ Master Threshold'!E114 -> 1 | J24: =IF(I24=0,"—",IF(F24<=I24,"🔴 KRITIS",IF(F24<=I24*2,"🟠 HAMPIR HABIS","🟢 AMAN"))) -> 🔴 KRITIS | L24: =IF(J24="🔴 KRITIS",B24,"") -> Thinwal 1250 ml | M24: =IF(J24="🔴 KRITIS","SEGERA RESTOCK!",IF(J24="🟠 HAMPIR HABIS","Cek & Restock","")) -> SEGERA RESTOCK!
... A50: =A49+1 -> 44 | B50: Dus Silver | C50: 0 | D50: 0 | E50: pcs | F50: =C50+D50 -> 0 | H50: — | I50: ='⚙️ Master Threshold'!E140 -> 5 | J50: =IF(I50=0,"—",IF(F50<=I50,"🔴 KRITIS",IF(F50<=I50*2,"🟠 HAMPIR HABIS","🟢 AMAN"))) -> 🔴 KRITIS | L50: =IF(J50="🔴 KRITIS",B50,"") -> Dus Silver | M50: =IF(J50="🔴 KRITIS","SEGERA RESTOCK!",IF(J50="🟠 HAMPIR HABIS","Cek & Restock","")) -> SEGERA RESTOCK!
A51: TOTAL ITEM DICEK | F51: =COUNTA(B6:B50)-COUNTIF(B6:B50,"") -> 43 | G51: ITEM KRITIS: | J51: =COUNTIF(J6:J50,"🔴 KRITIS") -> 21 | K51: =COUNTIF(J6:J50,"🟠 HAMPIR HABIS")&" item hampir habis" -> 8 item hampir habis

Sheet Gas & Utilitas
A1: ⚡ PENCATATAN GAS, LISTRIK & UTILITAS HARIAN
A2: TANGGAL / HARI | C2: 46257 | E2: =TEXT(C2,"DDDD") -> Sunday
A4: No | B4: ITEM | C4: STATUS / QTY | D4: TANGGAL ISI / PAKAI | E4: KWH / SISA | F4: KETERANGAN
A5: 1 | B5: Gas 3Kg — Tabung 1 | C5: habis | D5: 46252 | F5: Kosong
A6: 2 | B6: Gas 3Kg — Tabung 2 | C6: Ada | D6: 46257 | F6: Baru
A7: 3 | B7: Gas 12Kg — Tabung 1 | C7: Habis | D7: 19 Aug 2026 dipakai | F7: Kosong
A8: 4 | B8: Gas 12Kg — Tabung 2 | C8: habis | D8: 8 Agustus/dipakai 9 agustus | F8: Kosong
A9: 5 | B9: Token Listrik (KWH) | C9: Ada | E9: 1436 | F9: 22.1
A10: 6 | B10: Ganti Minyak Goreng | C10: Ada | D10: 19 Agustus 2026
A11: 7 | B11: Catatan Lain | C11: Ada

Sheet 📊 Dashboard Rekap
A1: 📊 DASHBOARD REKAP STOK OPNAME HARIAN
A2: Tanggal Laporan: | D2: ='Meja Biru + Chiller'!C2 -> 8/23/2026
A4: No | B4: AREA / SHEET | C4: Total Item | D4: 🔴 KRITIS | E4: 🟠 HAMPIR HABIS | F4: 🟢 AMAN | G4: % Kritis
A5: 1 | B5: Meja Biru Depan + Chiller | C5: =COUNTA('Meja Biru + Chiller'!B:B)-COUNTIF('Meja Biru + Chiller'!B:B,"")-1 -> -148 | D5: =COUNTIF('Meja Biru + Chiller'!J:J,"🔴 KRITIS") -> 11 | E5: =COUNTIF('Meja Biru + Chiller'!J:J,"🟠 HAMPIR HABIS") -> 7 | F5: =COUNTIF('Meja Biru + Chiller'!J:J,"🟢 AMAN") -> 35 | G5: =IF(C5=0,"—",D5/C5) -> -7%
A6: 2 | B6: Freezer & Alat | C6: =COUNTA('Freezer & Alat'!B:B)-COUNTIF('Freezer & Alat'!B:B,"")-1 -> -177 | D6: =COUNTIF('Freezer & Alat'!J:J,"🔴 KRITIS") -> 15 | E6: =COUNTIF('Freezer & Alat'!J:J,"🟠 HAMPIR HABIS") -> 4 | F6: =COUNTIF('Freezer & Alat'!J:J,"🟢 AMAN") -> 11 | G6: =IF(C6=0,"—",D6/C6) -> -8%
A7: 3 | B7: Meja Laci (Packaging) | C7: #REF! | D7: #REF! | E7: #REF! | F7: #REF! | G7: =IF(C7=0,"—",D7/C7) -> #VALUE!
A8: TOTAL KESELURUHAN | C8: =SUM(C5:C7) -> -325 | D8: =SUM(D5:D7) -> 26 | E8: =SUM(E5:E7) -> 11 | F8: =SUM(F5:F7) -> 46 | G8: =IF(C8=0,"—",D8/C8) -> -8%
A11: 📌 PANDUAN PENGISIAN STOK OPNAME
A12: 1️⃣ Buka sheet sesuai area (Meja Biru + Chiller / Freezer & Alat / Meja Laci)
A13: 2️⃣ Isi kolom STEP 1 (Hitung Utuh — stok yang masih dalam kemasan utuh)
A14: 3️⃣ Isi kolom STEP 2 (Hitung Terbuka — stok yang sudah terbuka / tidak utuh)
A15: 4️⃣ Kolom TOTAL akan otomatis terhitung (Step 1 + Step 2)
A16: 5️⃣ Kolom STATUS otomatis: 🔴 KRITIS = stok ≤ threshold | 🟠 HAMPIR HABIS = stok ≤ 2× threshold | 🟢 AMAN
A17: 6️⃣ Kolom REQUEST otomatis muncul item yang perlu direstok
A18: 7️⃣ Lihat sheet '📊 Dashboard Rekap' untuk ringkasan semua area
A19: ⚠️ Sel berwarna KUNING = sel input yang perlu diisi. Jangan ubah sel lainnya!
